<?xml version = "1.0" ?>
<robot xmlns:xacro = "http://www.ros.org/wiki/xacro">

<!--######################################################################-->
<xacro:macro name = "wheel_FL_RR"  params= "prefix originxy">
<link name = "${prefix}_link">
	<visual>
		<geometry>
			<mesh filename = "package://gyrobot/meshes/mecanum_clockwise.stl" scale = "0.01 0.01 0.01"/>
		</geometry>
		<material name ="white"/>
	</visual>
	<inertial>
		<origin
			xyz = "0 -0.000105 0" rpy = "0 0 0 "/>
		<mass value= "3.541238"/>
		<inertia ixx= "0.008808220" ixy = "0" ixz="0"
			iyy= "0.00877596" iyz = "0" izz="0.011661163"/>
	</inertial>
	<collision>
		<geometry>
			<mesh filename="package://gyrobot/meshes/mecanum_clockwise.stl" scale = "0.01 0.01 0.01"/>
		</geometry>
	</collision>
</link>

<joint name = "${prefix}_joint" type = "continuous">
	<parent link = "base_link"/>
	<child link = "${prefix}_link"/>
	<origin xyz = "${originxy} 0" rpy = "-1.57 0 0"/>
	<axis xyz = "0 0 1"/>
	<dynamics damping = "3.0" friction = "5.0"/>
</joint>
</xacro:macro>

<!--######################################################################-->

<xacro:macro name="wheel_FL_RR_transmission" params="prefix ">
<transmission name="${prefix}_trans" type="SimpleTransmission">
  <type>transmission_interface/SimpleTransmission</type>
  <actuator name="${prefix}_motor">
   <hardwareInterface>hardware_interface/VelocityJointInterface</hardwareInterface>
   <mechanicalReduction>1</mechanicalReduction>
  </actuator>
  <joint name="${prefix}_joint">
   <hardwareInterface>hardware_interface/VelocityJointInterface</hardwareInterface>
  </joint>
</transmission>
</xacro:macro>

<!--######################################################################-->

  
  <xacro:macro name="wheel_FL_RR_friction" params="prefix">
	<gazebo reference="${prefix}_link">
	  <selfCollide>true</selfCollide>
	  <gravity>true</gravity>
	  <mu1>2</mu1>
	  <mu2>2</mu2>
	  <kp>1e10</kp>
	  <kd>1e6</kd>
	  <material>Gazebo/White</material>
	</gazebo>
	</xacro:macro>
	
<!--######################################################################-->

</robot>

